Workbook

Sheet 1_Inputs
A1: Symbol | B1: Meaning | C1: Value | D1: Unit | E1: Scaling class | F1: Source
A2: cr_nat | B2: National capture rate | C2: 0.9 | D2: dimensionless | E2: input | F2: design basis
A3: F_nat | B3: National fossil combustion CO2 | C3: 26475.187 | D3: t-CO2/y | E3: input | F3: harmonised inventory
A4: T_nat | B4: National total combustion CO2 | C4: 74621.269 | D4: t-CO2/y | E4: input | F4: harmonised inventory
A5: EF_nat | B5: National grid emission factor | C5: 0.423 | D5: t-CO2/MWh | E5: input | F5: MoEJ/METI utility-list national average; the source inventories used 0.433 (reference plant, CCU) and 0.438 (mineralization, capture unit); R1b: every electricity line of the nine capture pathways is evaluated at this value from its source MWh, and the explicit terms of S0 and R1-R3 are rebased from 0.433 as before
A6: E_aux | B6: Plant auxiliary electricity | C6: 24360 | D6: MWh/y | E6: FIXED | F6: harmonised inventory
A7: E_exp_base | B7: Baseline electricity export, no capture | C7: 43207 | D7: MWh/y | E7: FIXED | F7: harmonised inventory
A8: E_exp_cc | B8: Electricity export with capture | C8: 30120 | D8: MWh/y | E8: derived | F8: harmonised inventory
A9: P_steam | B9: Steam-extraction export penalty | C9: 13087 | D9: MWh/y | E9: CAP | F9: E_exp_base minus E_exp_cc
A11: Note | B11: P_steam is the reboiler-duty penalty of the capture unit. It follows the captured CO2, not the waste tonnage, and is therefore in the CAP class. carbon_balance_v2 held it fixed, which was inconsistent with its own scaling rule.
A12: Scaling factors | B12: s_cap = (cr x T) / (cr_nat x T_nat); s_F = F / F_nat; both dimensionless and equal to 1 at national conditions
A14: Per-pathway parameters. Sheets 3 and 6 compute every group from these cells with Excel formulas; no component value is typed in those sheets.
A15: ID | B15: class | C15: is capture | D15: E_proc MWh/y | E15: H_p t-CO2/y | F15: QA_p t-CO2/y | G15: QB_p t-CO2/y | H15: V_p t-CO2/y | I15: L_R,p t-CO2/y | J15: D_p t-CO2/y | K15: R_p t-CO2/y (R1 solvent) | L15: Tr_p t-CO2/y (R1 transport) | M15: C_p t-CO2/y | N15: verified national result
A17: S0 | B17: ref | C17: 0 | D17: 0 | E17: 0 | F17: 0 | G17: 0 | H17: 0 | I17: 0 | J17: 0 | K17: 0 | L17: 0 | M17: 234.27226 | N17: 18737.178
A18: M1 | B18: min | C18: 1 | D18: 46787.536 | E18: 0 | F18: 0 | G18: 0 | H18: 0 | I18: 7462.1269 | J18: 0 | K18: 1057.2277 | L18: 5653.657 | M18: 1092.6637 | N18: 30453.233
A19: M2 | B19: min | C19: 1 | D19: 21341.651 | E19: 0 | F19: 0 | G19: 0 | H19: 0 | I19: 4029.54 | J19: 0 | K19: 1057.2277 | L19: 8037.2638 | M19: 16413.913 | N19: 36176.619
A20: M3 | B20: min | C20: 1 | D20: 17762.326 | E20: 0 | F20: 0 | G20: 0 | H20: 0 | I20: 7428.9197 | J20: 0 | K20: 1057.2277 | L20: 336.69231 | M20: 28599.842 | N20: 40354.001
A21: M4 | B21: min | C21: 1 | D21: 38365.902 | E21: 0 | F21: 0 | G21: 0 | H21: 0 | I21: 840.36106 | J21: 0 | K21: 1057.2277 | L21: 306.17174 | M21: 63796.647 | N21: 81898.016
A22: G1 | B22: geo | C22: 1 | D22: 7380.7897 | E22: 0 | F22: 0 | G22: 0 | H22: 0 | I22: 0 | J22: 0 | K22: 1057.2277 | L22: 1567.4944 | M22: 980.10348 | N22: 6937.9383
A23: G2 | B23: geo | C23: 1 | D23: 7515.108 | E23: 0 | F23: 0 | G23: 0 | H23: 0 | I23: 0 | J23: 0 | K23: 1057.2277 | L23: 1567.4944 | M23: 980.10348 | N23: 6994.7549
A24: U1 | B24: ccu | C24: 1 | D24: 14761.116 | E24: 64320.14 | F24: 75264.556 | G24: 63527.689 | H24: 4400.0817 | I24: 0 | J24: 0 | K24: 1057.2277 | L24: 449.96625 | M24: 980.10348 | N24: 22098.246
A25: U2a | B25: ccu | C25: 1 | D25: 22498.825 | E25: 51523.678 | F25: 133921.13 | G25: 64012.243 | H25: 4701.14 | I25: 0 | J25: 0 | K25: 1057.2277 | L25: 449.96625 | M25: 980.10348 | N25: -45803.013
A26: U2b | B26: ccu | C26: 1 | D26: 22498.825 | E26: 51523.678 | F26: 82711.341 | G26: 12802.449 | H26: 4701.14 | I26: 0 | J26: 0 | K26: 1057.2277 | L26: 449.96625 | M26: 980.10348 | N26: -12762.153
A27: R1 | B27: cr | C27: 0 | D27: 357 | E27: 0 | F27: 0 | G27: 0 | H27: 0 | I27: 0 | J27: 17678 | K27: 0 | L27: 0 | M27: -8639.0172 | N27: -7663.1
A28: R2 | B28: cr | C28: 0 | D28: 357 | E28: 0 | F28: 0 | G28: 0 | H28: 0 | I28: 0 | J28: 17678 | K28: 0 | L28: 0 | M28: -8639.0172 | N28: -7663.1
A29: R3 | B29: cr | C29: 0 | D29: 780.20339 | E29: 0 | F29: 0 | G29: 0 | H29: 0 | I29: 0 | J29: 17650 | K29: 0 | L29: 0 | M29: -8651.2643 | N29: -7468.332
A31: Note | B31: QA_p is the cradle-to-grave burden of the displaced fossil product; QB_p is the combustion CO2 of the synthesised product, charged at the fossil share f = F / T of the captured stream. The net substitution credit is (QA_p - f x QB_p) x s_cap. V_p is the process vent (mixed basis), charged at f. L_R,p is the mineralization reactor loss only; the capture slip (1 - cr) F is charged once, explicitly. R1: R_p is the capture solvent burden (12 kg CO2-eq per t ww x 84,000 t, Bisinella et al. 2021, Table 4) plus the activated-carbon and NaOH capture-unit increments (0.1 kg per t-CO2 each, Fig. 2; 40.30 and 8.93 t/y), and Tr_p the transport term (CO2 to storage 20 kg per t-CO2 for G; ore rail/ship on the t-km basis for M1/M2; slag truck 5 km for M3/M4; CO2 truck 0.134 kg per t-km x 50 km for U), both class CAP. E_proc is the capture, compression and conversion electricity from source kWh (R1b, D7); for U1/U2a/U2b it includes the 15 kWh per t-CO2 capture line (D10a). R1c: every capture pathway carries the common 90 kWh/t capture + conditioning module; U adds tanker liquefaction 16 kWh/t; G (ship scenario) adds liquefaction 17.4 and unloading 2.5 kWh/t (G2, high-pressure well: pumping to injection pressure 4.5 kWh/t in place of 2.5 + 7, R1d) and Tr_p = ship fuel 22 kg per t-CO2 + 10 km road to port (E_PROC_ITEMS_R1C / TRANSPORT_ITEMS_R1C in model_parameters.json).

Sheet 2_Term_classification
A1: Pathway | B1: Inventory item | C1: Symbol | D1: Baseline value | E1: Baseline unit | F1: Conversion factor | G1: Final unit | H1: Class | I1: Scaling formula | J1: Random or deterministic | K1: Shared or pathway-specific | L1: Treatment A/B dependence | M1: Sign | N1: Source
A2: S0 | B2: Plant auxiliary electricity | C2: E_aux | D2: 24360 | E2: MWh/y | F2: EF | G2: t-CO2/y | H2: FIXED | I2: E_aux x EF | J2: random through EF | K2: EF shared by all pathways | L2: none | M2: + | N2: harmonised inventory
A3: S0 | B3: Baseline electricity export | C3: E_exp_base | D3: -43207 | E3: MWh/y | F3: EF | G3: t-CO2/y | H3: FIXED | I3: minus E_exp_base x EF | J3: random through EF | K3: EF shared by all pathways | L3: none | M3: - | N3: harmonised inventory
A4: S0 | B4: Steam generation burden | C4: n/a | D4: not separate | E4: MWh/y | F4: n/a | G4: t-CO2/y | H4: FIXED | I4: inside E_exp_base; same waste tonnage in every region | J4: deterministic | K4: shared by all pathways | L4: none | M4: n/a | N4: harmonised inventory
A5: S0 | B5: Steam-extraction export penalty | C5: N/A | D5: N/A | E5: N/A | F5: N/A | G5: N/A | H5: N/A | I5: N/A | J5: N/A | K5: N/A | L5: N/A | M5: N/A | N5: N/A
A6: S0 | B6: Capture electricity | C6: N/A | D6: N/A | E6: N/A | F6: N/A | G6: N/A | H6: N/A | I6: N/A | J6: N/A | K6: N/A | L6: N/A | M6: N/A | N6: N/A
A7: S0 | B7: CO2 compression electricity | C7: N/A | D7: N/A | E7: N/A | F7: N/A | G7: N/A | H7: N/A | I7: N/A | J7: N/A | K7: N/A | L7: N/A | M7: N/A | N7: N/A
A8: S0 | B8: Conversion electricity | C8: N/A | D8: N/A | E8: N/A | F8: N/A | G8: N/A | H8: N/A | I8: N/A | J8: N/A | K8: N/A | L8: N/A | M8: N/A | N8: N/A
A9: S0 | B9: Total capture, compression and conversion electricity | C9: N/A | D9: N/A | E9: N/A | F9: N/A | G9: N/A | H9: N/A | I9: N/A | J9: N/A | K9: N/A | L9: N/A | M9: N/A | N9: N/A
A10: S0 | B10: Pyrolysis electricity | C10: N/A | D10: N/A | E10: N/A | F10: N/A | G10: N/A | H10: N/A | I10: N/A | J10: N/A | K10: N/A | L10: N/A | M10: N/A | N10: N/A
A11: S0 | B11: Hydrogen demand | C11: N/A | D11: N/A | E11: N/A | F11: N/A | G11: N/A | H11: N/A | I11: N/A | J11: N/A | K11: N/A | L11: N/A | M11: N/A | N11: N/A
A12: S0 | B12: Direct fossil-carbon emission | C12: F | D12: 26475.187 | E12: t-CO2/y | F12: already CO2 | G12: t-CO2/y | H12: CARBON | I12: enters phi; see the carbon-flow rows below | J12: random | K12: F shared by all pathways | L12: none | M12: + | N12: national waste survey
A13: S0 | B13: Uncaptured fossil fraction | C13: N/A | D13: N/A | E13: N/A | F13: N/A | G13: N/A | H13: N/A | I13: N/A | J13: N/A | K13: N/A | L13: N/A | M13: N/A | N13: N/A
A14: S0 | B14: Mineralization reactor loss | C14: N/A | D14: N/A | E14: N/A | F14: N/A | G14: N/A | H14: N/A | I14: N/A | J14: N/A | K14: N/A | L14: N/A | M14: N/A | N14: N/A
A15: S0 | B15: CCU process vent | C15: N/A | D15: N/A | E15: N/A | F15: N/A | G15: N/A | H15: N/A | I15: N/A | J15: N/A | K15: N/A | L15: N/A | M15: N/A | N15: N/A
A16: S0 | B16: Product output | C16: N/A | D16: N/A | E16: N/A | F16: N/A | G16: N/A | H16: N/A | I16: N/A | J16: N/A | K16: N/A | L16: N/A | M16: N/A | N16: N/A
A17: S0 | B17: Displaced-product burden (cradle-to-grave) | C17: N/A | D17: N/A | E17: N/A | F17: N/A | G17: N/A | H17: N/A | I17: N/A | J17: N/A | K17: N/A | L17: N/A | M17: N/A | N17: N/A
A18: S0 | B18: Product fossil-combustion charge | C18: N/A | D18: N/A | E18: N/A | F18: N/A | G18: N/A | H18: N/A | I18: N/A | J18: N/A | K18: N/A | L18: N/A | M18: N/A | N18: N/A
A19: S0 | B19: Diverted plastic carbon | C19: N/A | D19: N/A | E19: N/A | F19: N/A | G19: N/A | H19: N/A | I19: N/A | J19: N/A | K19: N/A | L19: N/A | M19: N/A | N19: N/A
A20: S0 | B20: Permanent geological storage | C20: N/A | D20: N/A | E20: N/A | F20: N/A | G20: N/A | H20: N/A | I20: N/A | J20: N/A | K20: N/A | L20: N/A | M20: N/A | N20: N/A
A21: S0 | B21: Temporary product storage | C21: N/A | D21: N/A | E21: N/A | F21: N/A | G21: N/A | H21: N/A | I21: N/A | J21: N/A | K21: N/A | L21: N/A | M21: N/A | N21: N/A
A22: S0 | B22: Final atmospheric release | C22: N/A | D22: N/A | E22: N/A | F22: N/A | G22: N/A | H22: N/A | I22: N/A | J22: N/A | K22: N/A | L22: N/A | M22: N/A | N22: N/A
A23: S0 | B23: Capture solvent burden (R1 explicit) | C23: N/A | D23: N/A | E23: N/A | F23: N/A | G23: N/A | H23: N/A | I23: N/A | J23: N/A | K23: N/A | L23: N/A | M23: N/A | N23: N/A
A24: S0 | B24: Transport (R1 explicit: CO2 to storage / ore / slag / CO2 to synthesis) | C24: N/A | D24: N/A | E24: N/A | F24: N/A | G24: N/A | H24: N/A | I24: N/A | J24: N/A | K24: N/A | L24: N/A | M24: N/A | N24: N/A
... A26: S0 | B26: Capital-related burdens | C26: C_cap | D26: inside residual | E26: t-CO2/y | F26: annualised | G26: t-CO2/y | H26: RESIDUAL | I26: annualised, held at its national value, x m_rem | J26: random through m_rem | K26: pathway-specific | L26: none | M26: + | N26: calibrated remainder
A27: S0 | B27: Calibrated residual, total | C27: C_p | D27: 234.27 | E27: t-CO2/y | F27: already CO2 | G27: t-CO2/y | H27: RESIDUAL | I27: C_p x m_rem | J27: random through m_rem | K27: pathway-specific | L27: shifts with the anchor under B | M27: +/- | N27: verified national value minus the explicit groups
A28: M1 | B28: Plant auxiliary electricity | C28: E_aux | D28: 24360 | E28: MWh/y | F28: EF | G28: t-CO2/y | H28: FIXED | I28: E_aux x EF | J28: random through EF | K28: EF shared by all pathways | L28: none | M28: + | N28: harmonised inventory
A29: M1 | B29: Baseline electricity export | C29: E_exp_base | D29: -43207 | E29: MWh/y | F29: EF | G29: t-CO2/y | H29: FIXED | I29: minus E_exp_base x EF | J29: random through EF | K29: EF shared by all pathways | L29: none | M29: - | N29: harmonised inventory
A30: M1 | B30: Steam generation burden | C30: n/a | D30: not separate | E30: MWh/y | F30: n/a | G30: t-CO2/y | H30: FIXED | I30: inside E_exp_base; same waste tonnage in every region | J30: deterministic | K30: shared by all pathways | L30: none | M30: n/a | N30: harmonised inventory
A31: M1 | B31: Steam-extraction export penalty | C31: P_steam | D31: 13087 | E31: MWh/y | F31: EF | G31: t-CO2/y | H31: CAP | I31: P_steam x s_cap x EF | J31: random through EF and cr | K31: EF and cr shared | L31: none | M31: + | N31: E_exp_base minus E_exp_cc
A32: M1 | B32: Capture electricity | C32: E_proc part | D32: inside E_proc | E32: MWh/y | F32: EF | G32: t-CO2/y | H32: CAP | I32: E_proc x s_cap x EF x m_el | J32: random | K32: m_el shared within family | L32: none | M32: + | N32: harmonised inventory
A33: M1 | B33: CO2 compression electricity | C33: E_proc part | D33: inside E_proc | E33: MWh/y | F33: EF | G33: t-CO2/y | H33: CAP | I33: E_proc x s_cap x EF x m_el | J33: random | K33: m_el shared within family | L33: none | M33: + | N33: harmonised inventory
A34: M1 | B34: Conversion electricity | C34: E_proc part | D34: inside E_proc | E34: MWh/y | F34: EF | G34: t-CO2/y | H34: CAP | I34: E_proc x s_cap x EF x m_el | J34: random | K34: m_el shared within family | L34: none | M34: + | N34: harmonised inventory
A35: M1 | B35: Total capture, compression and conversion electricity | C35: E_proc | D35: 46787.536 | E35: MWh/y | F35: EF | G35: t-CO2/y | H35: CAP | I35: E_proc x s_cap x EF x m_el | J35: random | K35: m_el shared within family | L35: none | M35: + | N35: harmonised inventory
A36: M1 | B36: Pyrolysis electricity | C36: N/A | D36: N/A | E36: N/A | F36: N/A | G36: N/A | H36: N/A | I36: N/A | J36: N/A | K36: N/A | L36: N/A | M36: N/A | N36: N/A
A37: M1 | B37: Hydrogen demand | C37: N/A | D37: N/A | E37: N/A | F37: N/A | G37: N/A | H37: N/A | I37: N/A | J37: N/A | K37: N/A | L37: N/A | M37: N/A | N37: N/A
A38: M1 | B38: Direct fossil-carbon emission | C38: F | D38: 26475.187 | E38: t-CO2/y | F38: already CO2 | G38: t-CO2/y | H38: CARBON | I38: enters phi; see the carbon-flow rows below | J38: random | K38: F shared by all pathways | L38: none | M38: + | N38: national waste survey
A39: M1 | B39: Uncaptured fossil fraction | C39: (1-cr) F | D39: applies | E39: t-CO2/y | F39: already CO2 | G39: t-CO2/y | H39: CARBON | I39: (1 - cr) x F, charged exactly once | J39: random through cr | K39: cr shared by capture pathways | L39: none | M39: + | N39: model
A40: M1 | B40: Mineralization reactor loss | C40: L_R,p | D40: 7462.1269 | E40: t-CO2/y | F40: already CO2 | G40: t-CO2/y | H40: CAP | I40: L_R x s_cap x f, inside phi (f = F / T, fossil share) | J40: random | K40: pathway-specific | L40: none | M40: + | N40: source workbook, reactor loss only
A41: M1 | B41: CCU process vent | C41: N/A | D41: N/A | E41: N/A | F41: N/A | G41: N/A | H41: N/A | I41: N/A | J41: N/A | K41: N/A | L41: N/A | M41: N/A | N41: N/A
...

Sheet 3_Eq2_national
A1: Pathway | B1: s_cap (formula) | C1: b_fix (formula) | D1: b_steam (formula) | E1: b_el (formula) | F1: phi (formula) | G1: b_h2 (formula) | H1: b_reag (formula, R1) | I1: b_trans (formula, R1) | J1: C_p (link) | K1: Eq.2 total (formula) | L1: Verified national value | M1: Difference (formula)
A2: S0 | B2: =('1_Inputs'!$C$4*'1_Inputs'!$C$2)/('1_Inputs'!$C$4*'1_Inputs'!$C$2) | C2: =('1_Inputs'!$C$6-'1_Inputs'!$C$7)*'1_Inputs'!$C$5 | D2: =0 | E2: ='1_Inputs'!D17*'1_Inputs'!$C$5 | F2: ='1_Inputs'!$C$3 | G2: ='1_Inputs'!E17*B2 | H2: ='1_Inputs'!K17*B2 | I2: ='1_Inputs'!L17*B2 | J2: ='1_Inputs'!M17 | K2: =SUM(C2:J2) | L2: ='1_Inputs'!N17 | M2: =K2-L2
A3: M1 | B3: =('1_Inputs'!$C$4*'1_Inputs'!$C$2)/('1_Inputs'!$C$4*'1_Inputs'!$C$2) | C3: =('1_Inputs'!$C$6-'1_Inputs'!$C$7)*'1_Inputs'!$C$5 | D3: ='1_Inputs'!$C$9*B3*'1_Inputs'!$C$5 | E3: ='1_Inputs'!D18*B3*'1_Inputs'!$C$5 | F3: =(1-'1_Inputs'!$C$2)*'1_Inputs'!$C$3+'1_Inputs'!I18*B3*('1_Inputs'!$C$3/'1_Inputs'!$C$4) | G3: ='1_Inputs'!E18*B3 | H3: ='1_Inputs'!K18*B3 | I3: ='1_Inputs'!L18*B3 | J3: ='1_Inputs'!M18 | K3: =SUM(C3:J3) | L3: ='1_Inputs'!N18 | M3: =K3-L3
A4: M2 | B4: =('1_Inputs'!$C$4*'1_Inputs'!$C$2)/('1_Inputs'!$C$4*'1_Inputs'!$C$2) | C4: =('1_Inputs'!$C$6-'1_Inputs'!$C$7)*'1_Inputs'!$C$5 | D4: ='1_Inputs'!$C$9*B4*'1_Inputs'!$C$5 | E4: ='1_Inputs'!D19*B4*'1_Inputs'!$C$5 | F4: =(1-'1_Inputs'!$C$2)*'1_Inputs'!$C$3+'1_Inputs'!I19*B4*('1_Inputs'!$C$3/'1_Inputs'!$C$4) | G4: ='1_Inputs'!E19*B4 | H4: ='1_Inputs'!K19*B4 | I4: ='1_Inputs'!L19*B4 | J4: ='1_Inputs'!M19 | K4: =SUM(C4:J4) | L4: ='1_Inputs'!N19 | M4: =K4-L4
A5: M3 | B5: =('1_Inputs'!$C$4*'1_Inputs'!$C$2)/('1_Inputs'!$C$4*'1_Inputs'!$C$2) | C5: =('1_Inputs'!$C$6-'1_Inputs'!$C$7)*'1_Inputs'!$C$5 | D5: ='1_Inputs'!$C$9*B5*'1_Inputs'!$C$5 | E5: ='1_Inputs'!D20*B5*'1_Inputs'!$C$5 | F5: =(1-'1_Inputs'!$C$2)*'1_Inputs'!$C$3+'1_Inputs'!I20*B5*('1_Inputs'!$C$3/'1_Inputs'!$C$4) | G5: ='1_Inputs'!E20*B5 | H5: ='1_Inputs'!K20*B5 | I5: ='1_Inputs'!L20*B5 | J5: ='1_Inputs'!M20 | K5: =SUM(C5:J5) | L5: ='1_Inputs'!N20 | M5: =K5-L5
A6: M4 | B6: =('1_Inputs'!$C$4*'1_Inputs'!$C$2)/('1_Inputs'!$C$4*'1_Inputs'!$C$2) | C6: =('1_Inputs'!$C$6-'1_Inputs'!$C$7)*'1_Inputs'!$C$5 | D6: ='1_Inputs'!$C$9*B6*'1_Inputs'!$C$5 | E6: ='1_Inputs'!D21*B6*'1_Inputs'!$C$5 | F6: =(1-'1_Inputs'!$C$2)*'1_Inputs'!$C$3+'1_Inputs'!I21*B6*('1_Inputs'!$C$3/'1_Inputs'!$C$4) | G6: ='1_Inputs'!E21*B6 | H6: ='1_Inputs'!K21*B6 | I6: ='1_Inputs'!L21*B6 | J6: ='1_Inputs'!M21 | K6: =SUM(C6:J6) | L6: ='1_Inputs'!N21 | M6: =K6-L6
A7: G1 | B7: =('1_Inputs'!$C$4*'1_Inputs'!$C$2)/('1_Inputs'!$C$4*'1_Inputs'!$C$2) | C7: =('1_Inputs'!$C$6-'1_Inputs'!$C$7)*'1_Inputs'!$C$5 | D7: ='1_Inputs'!$C$9*B7*'1_Inputs'!$C$5 | E7: ='1_Inputs'!D22*B7*'1_Inputs'!$C$5 | F7: =(1-'1_Inputs'!$C$2)*'1_Inputs'!$C$3 | G7: ='1_Inputs'!E22*B7 | H7: ='1_Inputs'!K22*B7 | I7: ='1_Inputs'!L22*B7 | J7: ='1_Inputs'!M22 | K7: =SUM(C7:J7) | L7: ='1_Inputs'!N22 | M7: =K7-L7
A8: G2 | B8: =('1_Inputs'!$C$4*'1_Inputs'!$C$2)/('1_Inputs'!$C$4*'1_Inputs'!$C$2) | C8: =('1_Inputs'!$C$6-'1_Inputs'!$C$7)*'1_Inputs'!$C$5 | D8: ='1_Inputs'!$C$9*B8*'1_Inputs'!$C$5 | E8: ='1_Inputs'!D23*B8*'1_Inputs'!$C$5 | F8: =(1-'1_Inputs'!$C$2)*'1_Inputs'!$C$3 | G8: ='1_Inputs'!E23*B8 | H8: ='1_Inputs'!K23*B8 | I8: ='1_Inputs'!L23*B8 | J8: ='1_Inputs'!M23 | K8: =SUM(C8:J8) | L8: ='1_Inputs'!N23 | M8: =K8-L8
A9: U1 | B9: =('1_Inputs'!$C$4*'1_Inputs'!$C$2)/('1_Inputs'!$C$4*'1_Inputs'!$C$2) | C9: =('1_Inputs'!$C$6-'1_Inputs'!$C$7)*'1_Inputs'!$C$5 | D9: ='1_Inputs'!$C$9*B9*'1_Inputs'!$C$5 | E9: ='1_Inputs'!D24*B9*'1_Inputs'!$C$5 | F9: =(1-'1_Inputs'!$C$2)*'1_Inputs'!$C$3+'1_Inputs'!H24*B9*('1_Inputs'!$C$3/'1_Inputs'!$C$4)-('1_Inputs'!F24-('1_Inputs'!$C$3/'1_Inputs'!$C$4)*'1_Inputs'!G24)*B9 | G9: ='1_Inputs'!E24*B9 | H9: ='1_Inputs'!K24*B9 | I9: ='1_Inputs'!L24*B9 | J9: ='1_Inputs'!M24 | K9: =SUM(C9:J9) | L9: ='1_Inputs'!N24 | M9: =K9-L9
A10: U2a | B10: =('1_Inputs'!$C$4*'1_Inputs'!$C$2)/('1_Inputs'!$C$4*'1_Inputs'!$C$2) | C10: =('1_Inputs'!$C$6-'1_Inputs'!$C$7)*'1_Inputs'!$C$5 | D10: ='1_Inputs'!$C$9*B10*'1_Inputs'!$C$5 | E10: ='1_Inputs'!D25*B10*'1_Inputs'!$C$5 | F10: =(1-'1_Inputs'!$C$2)*'1_Inputs'!$C$3+'1_Inputs'!H25*B10*('1_Inputs'!$C$3/'1_Inputs'!$C$4)-('1_Inputs'!F25-('1_Inputs'!$C$3/'1_Inputs'!$C$4)*'1_Inputs'!G25)*B10 | G10: ='1_Inputs'!E25*B10 | H10: ='1_Inputs'!K25*B10 | I10: ='1_Inputs'!L25*B10 | J10: ='1_Inputs'!M25 | K10: =SUM(C10:J10) | L10: ='1_Inputs'!N25 | M10: =K10-L10
A11: U2b | B11: =('1_Inputs'!$C$4*'1_Inputs'!$C$2)/('1_Inputs'!$C$4*'1_Inputs'!$C$2) | C11: =('1_Inputs'!$C$6-'1_Inputs'!$C$7)*'1_Inputs'!$C$5 | D11: ='1_Inputs'!$C$9*B11*'1_Inputs'!$C$5 | E11: ='1_Inputs'!D26*B11*'1_Inputs'!$C$5 | F11: =(1-'1_Inputs'!$C$2)*'1_Inputs'!$C$3+'1_Inputs'!H26*B11*('1_Inputs'!$C$3/'1_Inputs'!$C$4)-('1_Inputs'!F26-('1_Inputs'!$C$3/'1_Inputs'!$C$4)*'1_Inputs'!G26)*B11 | G11: ='1_Inputs'!E26*B11 | H11: ='1_Inputs'!K26*B11 | I11: ='1_Inputs'!L26*B11 | J11: ='1_Inputs'!M26 | K11: =SUM(C11:J11) | L11: ='1_Inputs'!N26 | M11: =K11-L11
A12: R1 | B12: =('1_Inputs'!$C$4*'1_Inputs'!$C$2)/('1_Inputs'!$C$4*'1_Inputs'!$C$2) | C12: =('1_Inputs'!$C$6-'1_Inputs'!$C$7)*'1_Inputs'!$C$5 | D12: =0 | E12: ='1_Inputs'!D27*('1_Inputs'!$C$3/'1_Inputs'!$C$3)*'1_Inputs'!$C$5 | F12: ='1_Inputs'!$C$3-'1_Inputs'!J27*('1_Inputs'!$C$3/'1_Inputs'!$C$3) | G12: ='1_Inputs'!E27*B12 | H12: ='1_Inputs'!K27*B12 | I12: ='1_Inputs'!L27*B12 | J12: ='1_Inputs'!M27 | K12: =SUM(C12:J12) | L12: ='1_Inputs'!N27 | M12: =K12-L12
A13: R2 | B13: =('1_Inputs'!$C$4*'1_Inputs'!$C$2)/('1_Inputs'!$C$4*'1_Inputs'!$C$2) | C13: =('1_Inputs'!$C$6-'1_Inputs'!$C$7)*'1_Inputs'!$C$5 | D13: =0 | E13: ='1_Inputs'!D28*('1_Inputs'!$C$3/'1_Inputs'!$C$3)*'1_Inputs'!$C$5 | F13: ='1_Inputs'!$C$3-'1_Inputs'!J28*('1_Inputs'!$C$3/'1_Inputs'!$C$3) | G13: ='1_Inputs'!E28*B13 | H13: ='1_Inputs'!K28*B13 | I13: ='1_Inputs'!L28*B13 | J13: ='1_Inputs'!M28 | K13: =SUM(C13:J13) | L13: ='1_Inputs'!N28 | M13: =K13-L13
A14: R3 | B14: =('1_Inputs'!$C$4*'1_Inputs'!$C$2)/('1_Inputs'!$C$4*'1_Inputs'!$C$2) | C14: =('1_Inputs'!$C$6-'1_Inputs'!$C$7)*'1_Inputs'!$C$5 | D14: =0 | E14: ='1_Inputs'!D29*('1_Inputs'!$C$3/'1_Inputs'!$C$3)*'1_Inputs'!$C$5 | F14: ='1_Inputs'!$C$3-'1_Inputs'!J29*('1_Inputs'!$C$3/'1_Inputs'!$C$3) | G14: ='1_Inputs'!E29*B14 | H14: ='1_Inputs'!K29*B14 | I14: ='1_Inputs'!L29*B14 | J14: ='1_Inputs'!M29 | K14: =SUM(C14:J14) | L14: ='1_Inputs'!N29 | M14: =K14-L14
A16: Max abs difference | B16: =MAX(MAX(M2:M15),-MIN(M2:M15))
A17: Note | B17: Every cell in columns B to K is an Excel formula that reads the parameters from 1_Inputs. Nothing in this sheet is a pasted component value, so the sheet recomputes if any input is changed.

Sheet 4_Eq2_vs_Eq6
A1: Pathway | B1: Eq.2 deterministic | C1: Eq.6 A, all multipliers = 1 | D1: Difference (formula) | E1: Eq.6 B, all multipliers = 1 | F1: B minus A (formula) | G1: D_p, expected B minus A | H1: Tolerance
A2: S0 | B2: 18737.178 | C2: 18737.178 | D2: =B2-C2 | E2: 18737.178 | F2: =E2-C2 | G2: 0 | H2: 1e-09
A3: M1 | B3: 30453.233 | C3: 30453.233 | D3: =B3-C3 | E3: 30453.233 | F3: =E3-C3 | G3: 0 | H3: 1e-09
A4: M2 | B4: 36176.619 | C4: 36176.619 | D4: =B4-C4 | E4: 36176.619 | F4: =E4-C4 | G4: 0 | H4: 1e-09
A5: M3 | B5: 40354.001 | C5: 40354.001 | D5: =B5-C5 | E5: 40354.001 | F5: =E5-C5 | G5: 0 | H5: 1e-09
A6: M4 | B6: 81898.016 | C6: 81898.016 | D6: =B6-C6 | E6: 81898.016 | F6: =E6-C6 | G6: 0 | H6: 1e-09
A7: G1 | B7: 6937.9383 | C7: 6937.9383 | D7: =B7-C7 | E7: 6937.9383 | F7: =E7-C7 | G7: 0 | H7: 1e-09
A8: G2 | B8: 6994.7549 | C8: 6994.7549 | D8: =B8-C8 | E8: 6994.7549 | F8: =E8-C8 | G8: 0 | H8: 1e-09
A9: U1 | B9: 22098.246 | C9: 22098.246 | D9: =B9-C9 | E9: 22098.246 | F9: =E9-C9 | G9: 0 | H9: 1e-09
A10: U2a | B10: -45803.013 | C10: -45803.013 | D10: =B10-C10 | E10: -45803.013 | F10: =E10-C10 | G10: 0 | H10: 1e-09
A11: U2b | B11: -12762.153 | C11: -12762.153 | D11: =B11-C11 | E11: -12762.153 | F11: =E11-C11 | G11: 0 | H11: 1e-09
A12: R1 | B12: -7663.1 | C12: -7663.1 | D12: =B12-C12 | E12: 10014.9 | F12: =E12-C12 | G12: 17678 | H12: 1e-09
A13: R2 | B13: -7663.1 | C13: -7663.1 | D13: =B13-C13 | E13: 10014.9 | F13: =E13-C13 | G13: 17678 | H13: 1e-09
A14: R3 | B14: -7468.332 | C14: -7468.332 | D14: =B14-C14 | E14: 10181.668 | F14: =E14-C14 | G14: 17650 | H14: 1e-09
A16: Max abs difference | B16: =MAX(MAX(D2:D15),-MIN(D2:D15))
A17: Interpretation | B17: Eq.2 and Eq.6 are one model written in two groupings. A non-zero value in column D would mean they are not.

Sheet 5_Shapley
A1: Pathway | B1: g0w0h0 | C1: g0w0h1 | D1: g0w1h0 | E1: g0w1h1 | F1: g1w0h0 | G1: g1w0h1 | H1: g1w1h0 | I1: g1w1h1 | J1: Total change (formula) | K1: Shapley grid | L1: Shapley waste | M1: Shapley H2 | N1: Sum (formula) | O1: Closure (formula)
A2: S0 | B2: 18737.178 | C2: 18737.178 | D2: 2677.9913 | E2: 2677.9913 | F2: 25390.169 | G2: 25390.169 | H2: 9330.9823 | I2: 9330.9823 | J2: =I2-B2 | K2: 6652.991 | L2: -16059.187 | M2: 0 | N2: =SUM(K2:M2) | O2: =J2-N2
A3: M1 | B3: 30453.233 | C3: 30453.233 | D3: 20701.161 | E3: 20701.161 | F3: 15970.513 | G3: 15970.513 | H3: 10533.109 | I3: 10533.109 | J3: =I3-B3 | K3: -12325.386 | L3: -7594.7386 | M3: 0 | N3: =SUM(K3:M3) | O3: =J3-N3
A4: M2 | B4: 36176.619 | C4: 36176.619 | D4: 28873.974 | E4: 28873.974 | F4: 30676.296 | G4: 30676.296 | H4: 25854.642 | I4: 25854.642 | J4: =I4-B4 | K4: -4259.8271 | L4: -6062.1494 | M4: 0 | N4: =SUM(K4:M4) | O4: =J4-N4
A5: M3 | B5: 40354.001 | C5: 40354.001 | D5: 34200.863 | E5: 34200.863 | F5: 36117.18 | G5: 36117.18 | H5: 32187.1 | I5: 32187.1 | J5: =I5-B5 | K5: -3125.2919 | L5: -5041.6096 | M5: 0 | N5: =SUM(K5:M5) | O5: =J5-N5
A6: M4 | B6: 81898.016 | C6: 81898.016 | D6: 75389.873 | E6: 75389.873 | F6: 70388.133 | G6: 70388.133 | H6: 67587.779 | I6: 67587.779 | J6: =I6-B6 | K6: -9655.9886 | L6: -4654.2485 | M6: 0 | N6: =SUM(K6:M6) | O6: =J6-N6
A7: G1 | B7: 6937.9383 | C7: 6937.9383 | D7: 3028.7776 | E7: 3028.7776 | F7: 6365.7995 | G7: 6365.7995 | H7: 3931.5849 | I7: 3931.5849 | J7: =I7-B7 | K7: 165.33425 | L7: -3171.6877 | M7: 0 | N7: =SUM(K7:M7) | O7: =J7-N7
A8: G2 | B8: 6994.7549 | C8: 6994.7549 | D8: 3073.9956 | E8: 3073.9956 | F8: 6375.2018 | G8: 6375.2018 | H8: 3939.0678 | I8: 3939.0678 | J8: =I8-B8 | K8: 122.75951 | L8: -3178.4467 | M8: 0 | N8: =SUM(K8:M8) | O8: =J8-N8
A9: U1 | B9: 22098.246 | C9: -470.90812 | D9: 5395.4357 | E9: -12566.426 | F9: 18920.852 | G9: -3648.3022 | H9: 4224.8274 | I9: -13737.034 | J9: =I9-B9 | K9: -2174.0012 | L9: -13395.771 | M9: -20265.508 | N9: =SUM(K9:M9) | O9: =J9-N9
A10: U2a | B10: -45803.013 | C10: -63882.045 | D10: -48756.555 | E10: -63144.913 | F10: -51711.819 | G10: -69790.85 | H10: -52100.982 | I10: -66489.339 | J10: =I10-B10 | K10: -4626.6158 | L10: 173.98451 | M10: -16233.695 | N10: =SUM(K10:M10) | O10: =J10-N10
A11: U2b | B11: -12762.153 | C11: -30841.184 | D11: -15148.898 | E11: -29537.256 | F11: -18670.958 | G11: -36749.99 | H11: -18493.324 | I11: -32881.682 | J11: =I11-B11 | K11: -4626.6158 | L11: 740.78125 | M11: -16233.695 | N11: =SUM(K11:M11) | O11: =J11-N11
A12: R1 | B12: -7663.1 | C12: -7663.1 | D12: -13090.853 | E12: -13090.853 | F12: -1136.13 | G12: -1136.13 | H12: -6487.4423 | I12: -6487.4423 | J12: =I12-B12 | K12: 6565.1906 | L12: -5389.5329 | M12: 0 | N12: =SUM(K12:M12) | O12: =J12-N12
A13: R2 | B13: -7663.1 | C13: -7663.1 | D13: -13090.853 | E13: -13090.853 | F13: -1136.13 | G13: -1136.13 | H13: -6487.4423 | I13: -6487.4423 | J13: =I13-B13 | K13: 6565.1906 | L13: -5389.5329 | M13: 0 | N13: =SUM(K13:M13) | O13: =J13-N13
A14: R3 | B14: -7468.332 | C14: -7468.332 | D14: -13021.656 | E14: -13021.656 | F14: -1090.7528 | G14: -1090.7528 | H14: -6477.0186 | I14: -6477.0186 | J14: =I14-B14 | K14: 6461.1082 | L14: -5469.7947 | M14: 0 | N14: =SUM(K14:M14) | O14: =J14-N14
A16: Max abs closure | B16: =MAX(MAX(O2:O15),-MIN(O2:O15))

Sheet 6_Regional_130
A1: Pathway | B1: Region | C1: EF_r | D1: F_r | E1: T_r | F1: s_cap | G1: b_fix | H1: b_steam + b_el | I1: phi | J1: Q_sub inside phi | K1: b_h2 | L1: b_reag (R1) | M1: b_trans (R1) | N1: C_p residual | O1: Absolute (formula) | P1: Reference | Q1: Relative kt (formula) | R1: Fig.3 displayed kt | S1: Discrepancy (formula)
A2: S0 | B2: Chubu | C2: 0.393 | D2: 25673.686 | E2: 74679.606 | F2: 1.0007818 | G2: -7406.871 | H2: 0 | I2: 25673.686 | J2: 0 | K2: 0 | L2: 0 | M2: 0 | N2: 234.27226 | O2: =SUM(G2:I2,K2:N2) | P2: 18501.087
A3: S0 | B3: Chugoku | C3: 0.511 | D3: 23551.38 | E3: 74041.05 | F3: 0.99222448 | G3: -9630.817 | H3: 0 | I3: 23551.38 | J3: 0 | K3: 0 | L3: 0 | M3: 0 | N3: 234.27226 | O3: =SUM(G3:I3,K3:N3) | P3: 14154.835
A4: S0 | B4: Hokkaido | C4: 0.532 | D4: 23563.041 | E4: 72980.73 | F4: 0.97801513 | G4: -10026.604 | H4: 0 | I4: 23563.041 | J4: 0 | K4: 0 | L4: 0 | M4: 0 | N4: 234.27226 | O4: =SUM(G4:I4,K4:N4) | P4: 13770.709
A5: S0 | B5: Hokuriku | C5: 0.481 | D5: 26482.184 | E5: 75140.786 | F5: 1.0069621 | G5: -9065.407 | H5: 0 | I5: 26482.184 | J5: 0 | K5: 0 | L5: 0 | M5: 0 | N5: 234.27226 | O5: =SUM(G5:I5,K5:N5) | P5: 17651.049
A6: S0 | B6: Kansai | C6: 0.401 | D6: 29121.462 | E6: 74951.584 | F6: 1.0044266 | G6: -7557.647 | H6: 0 | I6: 29121.462 | J6: 0 | K6: 0 | L6: 0 | M6: 0 | N6: 234.27226 | O6: =SUM(G6:I6,K6:N6) | P6: 21798.087
A7: S0 | B7: Kyushu | C7: 0.402 | D7: 26567.698 | E7: 74541.647 | F7: 0.99893298 | G7: -7576.494 | H7: 0 | I7: 26567.698 | J7: 0 | K7: 0 | L7: 0 | M7: 0 | N7: 234.27226 | O7: =SUM(G7:I7,K7:N7) | P7: 19225.476
A8: S0 | B8: Okinawa | C8: 0.638 | D8: 30306.999 | E8: 76153.805 | F8: 1.0205375 | G8: -12024.386 | H8: 0 | I8: 30306.999 | J8: 0 | K8: 0 | L8: 0 | M8: 0 | N8: 234.27226 | O8: =SUM(G8:I8,K8:N8) | P8: 18516.886
A9: S0 | B9: Shikoku | C9: 0.454 | D9: 25386.048 | E9: 74230.252 | F9: 0.99475997 | G9: -8556.538 | H9: 0 | I9: 25386.048 | J9: 0 | K9: 0 | L9: 0 | M9: 0 | N9: 234.27226 | O9: =SUM(G9:I9,K9:N9) | P9: 17063.782
A10: S0 | B10: Tohoku | C10: 0.385 | D10: 26641.551 | E10: 74683.548 | F10: 1.0008346 | G10: -7256.095 | H10: 0 | I10: 26641.551 | J10: 0 | K10: 0 | L10: 0 | M10: 0 | N10: 234.27226 | O10: =SUM(G10:I10,K10:N10) | P10: 19619.728
A11: S0 | B11: Tokyo | C11: 0.408 | D11: 27457.823 | E11: 74809.683 | F11: 1.0025249 | G11: -7689.576 | H11: 0 | I11: 27457.823 | J11: 0 | K11: 0 | L11: 0 | M11: 0 | N11: 234.27226 | O11: =SUM(G11:I11,K11:N11) | P11: 20002.519
A12: M1 | B12: Chubu | C12: 0.393 | D12: 25673.686 | E12: 74679.606 | F12: 1.0007818 | G12: -7406.871 | H12: 23549.088 | I12: 5134.7372 | J12: 0 | K12: 0 | L12: 1058.0542 | M12: 5658.0769 | N12: 1092.6637 | O12: =SUM(G12:I12,K12:N12) | P12: 18501.087 | Q12: =(O12-P12)/1000 | R12: 10.585 | S12: =ABS(Q12-R12)
A13: M1 | B13: Chugoku | C13: 0.511 | D13: 23551.38 | E13: 74041.05 | F13: 0.99222448 | G13: -9630.817 | H13: 30357.989 | I13: 4710.276 | J13: 0 | K13: 0 | L13: 1049.0072 | M13: 5609.6968 | N13: 1092.6637 | O13: =SUM(G13:I13,K13:N13) | P13: 14154.835 | Q13: =(O13-P13)/1000 | R13: 19.034 | S13: =ABS(Q13-R13)
A14: M1 | B14: Hokkaido | C14: 0.532 | D14: 23563.041 | E14: 72980.73 | F14: 0.97801513 | G14: -10026.604 | H14: 31152.963 | I14: 4712.6082 | J14: 0 | K14: 0 | L14: 1033.9846 | M14: 5529.362 | N14: 1092.6637 | O14: =SUM(G14:I14,K14:N14) | P14: 13770.709 | Q14: =(O14-P14)/1000 | R14: 19.724 | S14: =ABS(Q14-R14)
A15: M1 | B15: Hokuriku | C15: 0.481 | D15: 26482.184 | E15: 75140.786 | F15: 1.0069621 | G15: -9065.407 | H15: 29000.156 | I15: 5296.4368 | J15: 0 | K15: 0 | L15: 1064.5881 | M15: 5693.018 | N15: 1092.6637 | O15: =SUM(G15:I15,K15:N15) | P15: 17651.049 | Q15: =(O15-P15)/1000 | R15: 15.43 | S15: =ABS(Q15-R15)
A16: M1 | B16: Kansai | C16: 0.401 | D16: 29121.462 | E16: 74951.584 | F16: 1.0044266 | G16: -7557.647 | H16: 24115.969 | I16: 5824.2924 | J16: 0 | K16: 0 | L16: 1061.9075 | M16: 5678.6832 | N16: 1092.6637 | O16: =SUM(G16:I16,K16:N16) | P16: 21798.087 | Q16: =(O16-P16)/1000 | R16: 8.418 | S16: =ABS(Q16-R16)
A17: M1 | B17: Kyushu | C17: 0.402 | D17: 26567.698 | E17: 74541.647 | F17: 0.99893298 | G17: -7576.494 | H17: 24043.881 | I17: 5313.5396 | J17: 0 | K17: 0 | L17: 1056.0996 | M17: 5647.6244 | N17: 1092.6637 | O17: =SUM(G17:I17,K17:N17) | P17: 19225.476 | Q17: =(O17-P17)/1000 | R17: 10.352 | S17: =ABS(Q17-R17)
A18: M1 | B18: Okinawa | C18: 0.638 | D18: 30306.999 | E18: 76153.805 | F18: 1.0205375 | G18: -12024.386 | H18: 38984.486 | I18: 6061.3999 | J18: 0 | K18: 0 | L18: 1078.9405 | M18: 5769.7691 | N18: 1092.6637 | O18: =SUM(G18:I18,K18:N18) | P18: 18516.886 | Q18: =(O18-P18)/1000 | R18: 22.446 | S18: =ABS(Q18-R18)
A19: M1 | B19: Shikoku | C19: 0.454 | D19: 25386.048 | E19: 74230.252 | F19: 0.99475997 | G19: -8556.538 | H19: 27040.599 | I19: 5077.2095 | J19: 0 | K19: 0 | L19: 1051.6878 | M19: 5624.0316 | N19: 1092.6637 | O19: =SUM(G19:I19,K19:N19) | P19: 17063.782 | Q19: =(O19-P19)/1000 | R19: 14.266 | S19: =ABS(Q19-R19)
A20: M1 | B20: Tohoku | C20: 0.385 | D20: 26641.551 | E20: 74683.548 | F20: 1.0008346 | G20: -7256.095 | H20: 23070.935 | I20: 5328.3102 | J20: 0 | K20: 0 | L20: 1058.11 | M20: 5658.3755 | N20: 1092.6637 | O20: =SUM(G20:I20,K20:N20) | P20: 19619.728 | Q20: =(O20-P20)/1000 | R20: 9.333 | S20: =ABS(Q20-R20)
A21: M1 | B21: Tokyo | C21: 0.408 | D21: 27457.823 | E21: 74809.683 | F21: 1.0025249 | G21: -7689.576 | H21: 24490.492 | I21: 5491.5646 | J21: 0 | K21: 0 | L21: 1059.8971 | M21: 5667.9321 | N21: 1092.6637 | O21: =SUM(G21:I21,K21:N21) | P21: 20002.519 | Q21: =(O21-P21)/1000 | R21: 10.11 | S21: =ABS(Q21-R21)
A22: M2 | B22: Chubu | C22: 0.393 | D22: 25673.686 | E22: 74679.606 | F22: 1.0007818 | G22: -7406.871 | H22: 13541.037 | I22: 3953.7447 | J22: 0 | K22: 0 | L22: 1058.0542 | M22: 8043.5471 | N22: 16413.913 | O22: =SUM(G22:I22,K22:N22) | P22: 18501.087 | Q22: =(O22-P22)/1000 | R22: 17.102 | S22: =ABS(Q22-R22)
A23: M2 | B23: Chugoku | C23: 0.511 | D23: 23551.38 | E23: 74041.05 | F23: 0.99222448 | G23: -9630.817 | H23: 17456.245 | I23: 3626.9098 | J23: 0 | K23: 0 | L23: 1049.0072 | M23: 7974.7698 | N23: 16413.913 | O23: =SUM(G23:I23,K23:N23) | P23: 14154.835 | Q23: =(O23-P23)/1000 | R23: 22.735 | S23: =ABS(Q23-R23)
... A131: R3 | B131: Tokyo | C131: 0.408 | D131: 27457.823 | E131: 74809.683 | F131: 1.0025249 | G131: -7689.576 | H131: 330.13765 | I131: 9152.737 | J131: 0 | K131: 0 | L131: 0 | M131: 0 | N131: -8651.2643 | O131: =SUM(G131:I131,K131:N131) | P131: 20002.519 | Q131: =(O131-P131)/1000 | R131: -26.86 | S131: =ABS(Q131-R131)
A133: Max discrepancy kt | C133: =MAX(S2:S131)

Sheet 7_Provenance
A1: Item | B1: Value
A2: Deterministic model | B2: carbon_model.py; constants from model_parameters.json, generated by derive_parameters.py from the source workbooks with per-cell assertions; R1: STATIC anchors, E_PROC_MWH (all 13), REAGENT_T / TRANSPORT_T from apply_r1_anchors.py + apply_r1b.py (P2B_corrected_anchors.json, P2B2_anchors.json); R1c conditioning, transport and storage items from apply_r1c.py + r1c_modules.py (03_new_sources/CONDITIONING_ENERGY_CANDIDATES.md); R1d audit corrections and the capital boundary from apply_r1d.py (CAPITAL_CAPTURE_T)
A3: Revision | B3: R1 chain copy, phase 2C + phase 2b (2026-09-19): itemised bottom-up G/M/U anchors with every electricity line at 0.423 from source MWh (D7), explicit solvent and transport groups (class CAP) with their own multipliers, plant APC chemicals outside the boundary (D6), CCU transport on the t-km basis (D9), CCU capture electricity in b_el (D10a), activated-carbon increment (D13), tonnage-weighted regional table (D12); R1c: unified modular boundary of the nine capture pathways (common 90 kWh/t module, U tanker liquefaction, G Japan-oriented ship scenario with liquefaction, receiving-side unloading 2.5 kWh/t for G1 and pumping to injection pressure 4.5 kWh/t for G2, ship fuel one way + road leg); R1d: plant light oil in G1/G2, capital goods = the capture unit only (745.649 t/y, 20-year divisor) in all nine capture pathways, inside C_p; S0 and R1-R3 carry no capital goods; declared scenarios via R1C_SCENARIO (SCAPU adds U synthesis capital, SL30 a 30-year life)
A4: Regional table | B4: R1e: region_waste_carbon.csv = 47 prefecture profiles rebuilt from the MoEJ FY2021 incineration-facility table by one rule (simple mean of the 920 facilities reporting a composition), aggregated to ten regions weighted by FY2021 直接焼却量 (base, W2a); region_waste_carbon_W1.csv = facility level, 900 facilities weighted by 年間処理量 (REGION_WEIGHTING=W1); region_waste_carbon_unweighted.csv = submitted unweighted aggregation (REGION_WEIGHTING=unweighted). Raw files, SHA-256 and rules: R1_revision/03_new_sources/MoEJ_FY2021/, R1_revision/02_analyses/R1e_regional/
A5: Monte Carlo model | B5: monte_carlo.py; master matrix generated by monte_carlo.build_master
A6: Scenario decomposition | B6: scenario_decomposition.py
A7: Regional data loader | B7: regional_model.py; regional input data loaded directly from region_waste_carbon.csv
A8: Machine-readable exports | B8: export_files.py
A9: This workbook | B9: build_workbook.py
A10: Python | B10: 3.11.9 on Windows-10-10.0.26200-SP0
A11: numpy | B11: 2.4.2
A12: openpyxl | B12: 3.1.5
... A20: Output mapping | B20: 1_Inputs and 3_Eq2_national -> Eq. 2 of the main text, recomputed with Excel formulas; 2_Term_classification -> SI Table S6; 6_Regional_130 -> SI Tables S22 and S23 and Fig3_source_data.csv; 5_Shapley -> Table 2 of the main text and SI Table S11; 4_Eq2_vs_Eq6 -> SI Table S12; C_p decomposition -> SI Table S8
